Workbook

Sheet 1 курс
A1: Дни | C1: Часы | F1: РУПО 11 | AR1: Ауд. | AU1: Дни | AW1: Часы | AZ1: РУПО 12 | CL1: Ауд.
A2: Недели | C2: Занятий | AU2: Недели | AW2: Занятий
A3: =Даты!$B$2&" "&Даты!$C$2 -> Понедельник 21.09 | C3: 8:30-9:30 | E3: 1 | AU3: =Даты!$B$2&" "&Даты!$C$2 -> Понедельник 21.09 | AW3: 8:30-9:30 | AY3: 1 | AZ3: Русский язык | CL3: 84
AZ4: Ватолина О.А.
C5: 10:00-11:00 | E5: 2 | AW5: 10:00-11:00 | AY5: 2 | AZ5: Физическая культура | CL5: Спорт зал
AZ6: Демченков В.А.
C7: 11:10-12:10 | E7: 3 | AW7: 11:10-12:10 | AY7: 3 | AZ7: Математика | CL7: 84
AZ8: Макарова Н.П.
C9: 12:10-12:55 | AW9: 12:10-12:55
C11: 12:55-13:40 | AW11: 12:55-13:40
C13: 13:40-14:40 | E13: 4 | F13: Русский язык | AR13: 74 | AW13: 13:40-14:40 | AY13: 4
F14: Ватолина О.А.
C15: 15:10-16:10 | E15: 5 | F15: Математика | AR15: 84 | AW15: 15:10-16:10 | AY15: 5
F16: Макарова Н.П.
C17: 16:20-17:20 | E17: 6 | F17: Физическая культура | AR17: Спорт зал | AW17: 16:20-17:20 | AY17: 6
F18: Демченков В.А.
C19: 17:30-18:30 | E19: 7 | F19: Биология | AR19: 84 | AW19: 17:30-18:30 | AY19: 7
F20: Худякова Н.А.
A21: =Даты!$B$3&" "&Даты!$C$3 -> Вторник 22.09 | C21: 8:30-10:00 | E21: 1 | AU21: =Даты!$B$3&" "&Даты!$C$3 -> Вторник 22.09 | AW21: 8:30-10:00 | AY21: 1
C23: 10:30-12:00 | E23: 2 | AW23: 10:30-12:00 | AY23: 2
C25: 12:10-13:40 | E25: 3 | F25: Информатика | AR25: 13 | AW25: 12:10-13:40 | AY25: 3 | AZ25: Русский язык | CL25: 89
F26: Тетенькин Д.А. | AZ26: Ватолина О.А.
C27: 13:50-15:20 | E27: 4 | F27: Математика | AR27: 84 | AW27: 13:50-15:20 | AY27: 4 | AZ27: Литература | CL27: 89
F28: Макарова Н.П. | AZ28: Перевозчикова Е.Н.
C29: 15:50-17:20 | E29: 5 | F29: ОБ и защиты Родины | AR29: 2 | AW29: 15:50-17:20 | AY29: 5 | AZ29: Обществознание | CL29: 89
F30: Деветьярова Е.А. | AZ30: Семакина Н.А.
C31: 17:30-19:00 | E31: 6 | F31: Физика | AR31: 90 | AW31: 17:30-19:00 | AY31: 6 | AZ31: Математика | CL31: 84
F32: Дектерева О.А. | AZ32: Макарова Н.П.
C33: 19:10-20:40 | E33: 7 | AW33: 19:10-20:40 | AY33: 7
A35: =Даты!$B$4&" "&Даты!$C$4 -> Среда 23.09 | C35: 8:30-10:00 | E35: 1 | F35: Литература | AR35: 89 | AU35: =Даты!$B$4&" "&Даты!$C$4 -> Среда 23.09 | AW35: 8:30-10:00 | AY35: 1
F36: Перевозчикова Е.Н.
C37: 10:30-12:00 | E37: 2 | F37: Биология | AR37: 89 | AW37: 10:30-12:00 | AY37: 2
F38: Худякова Н.А.
C39: 12:10-13:40 | E39: 3 | F39: Физика | AR39: 90 | AW39: 12:10-13:40 | AY39: 3 | AZ39: История | CL39: 84
F40: Дектерева О.А. | AZ40: Окулова Е.С.
C41: 13:50-15:20 | E41: 4 | F41: Русский язык | AR41: 89 | AW41: 13:50-15:20 | AY41: 4 | AZ41: Физика | CL41: 90
F42: Ватолина О.А. | AZ42: Дектерева О.А.
C43: 15:50-17:20 | E43: 5 | AW43: 15:50-17:20 | AY43: 5 | AZ43: История | CL43: 89
AZ44: Окулова Е.С.
C45: 17:30-19:00 | E45: 6 | AW45: 17:30-19:00 | AY45: 6 | AZ45: Обществознание | CL45: 89
...

Sheet 2 курс
A1: Дни | C1: Часы | F1: ИСП 21-9 | AR1: Ауд. | AU1: Дни | AW1: Часы | AZ1: ИСП 22-9, 24-11 | CL1: Ауд.
A2: Недели | C2: Занятий | AU2: Недели | AW2: Занятий
A3: =Даты!$B$2&" "&Даты!$C$2 -> Понедельник 21.09 | C3: 8:30-9:30 | E3: 1 | F3: Основы проектироания БД | AR3: 17 | AU3: =Даты!$B$2&" "&Даты!$C$2 -> Понедельник 21.09 | AW3: 8:30-9:30 | AY3: 1 | AZ3: Физическая культура | CL3: Спорт зал
F4: Красноперов К.В. | AZ4: Демченков В.А.
C5: 10:00-11:00 | E5: 2 | F5: Основы проектироания БД | AR5: 17 | AW5: 10:00-11:00 | AY5: 2 | AZ5: Архитектура аппаратных средств | CL5: 16
F6: Красноперов К.В. | AZ6: Тетенькин Д.А.
C7: 11:10-12:10 | E7: 3 | F7: Основы проектироания БД | AR7: 17 | AW7: 11:10-12:10 | AY7: 3 | AZ7: Иностранный язык в ПД | CL7: 2
F8: Красноперов К.В. | AZ8: Кусакина О.В,
C9: 12:10-12:55 | AW9: 12:10-12:55
C11: 12:55-13:40 | AW11: 12:55-13:40
C13: 13:40-14:40 | E13: 4 | AW13: 13:40-14:40 | AY13: 4
C15: 15:10-16:10 | E15: 5 | AW15: 15:10-16:10 | AY15: 5
C17: 16:20-17:20 | E17: 6 | AW17: 16:20-17:20 | AY17: 6
C19: 17:30-18:30 | E19: 7 | AW19: 17:30-18:30 | AY19: 7
A21: =Даты!$B$3&" "&Даты!$C$3 -> Вторник 22.09 | C21: 8:30-9:10 | E21: 1 | F21: Основы проектироания БД | AR21: 16 | AU21: =Даты!$B$3&" "&Даты!$C$3 -> Вторник 22.09 | AW21: 8:30-9:10 | AY21: 1 | AZ21: Элементы высшей математики | CL21: 17
F22: Красноперов К.В. | AZ22: Дектерева О.А.
C23: 09:20-10:00 | E23: 2 | F23: Основы проектироания БД | AR23: 16 | AW23: 09:20-10:00 | AY23: 2 | AZ23: Элементы высшей математики | CL23: 17
F24: Красноперов К.В. | AZ24: Дектерева О.А.
C25: 10:10-10:50 | E25: 3 | AW25: 10:10-10:50 | AY25: 3
C27: 12:00-12:40 | E27: 4 | AW27: 12:00-12:40 | AY27: 4
C29: 12:50-13:30 | E29: 5 | AW29: 12:50-13:30 | AY29: 5
C31: 13:40-14:20 | E31: 6 | AW31: 13:40-14:20 | AY31: 6
C33: 14:30-15:10 | E33: 7 | AW33: 14:30-15:10 | AY33: 7
A35: =Даты!$B$4&" "&Даты!$C$4 -> Среда 23.09 | C35: 8:30-10:00 | E35: 1 | F35: Безопасность жизнедеятельности | AR35: 2 | AU35: =Даты!$B$4&" "&Даты!$C$4 -> Среда 23.09 | AW35: 8:30-10:00 | AY35: 1
F36: Деветьярова Е.А.
C37: 10:30-12:00 | E37: 2 | F37: Элементы высшей математики | AR37: 7 | AW37: 10:30-12:00 | AY37: 2
F38: Дектерева О.А.
C39: 12:10-13:40 | E39: 3 | F39: Физическая культура | AR39: Спорт зал | AW39: 12:10-13:40 | AY39: 3 | AZ39: Основы проектироания БД | CL39: 17
F40: Демченков В.А. | AZ40: Красноперов К.В.
C41: 13:50-15:20 | E41: 4 | AW41: 13:50-15:20 | AY41: 4 | AZ41: Архитектура аппаратных средств | CL41: 57
AZ42: Тетенькин Д.А.
C43: 15:50-17:20 | E43: 5 | AW43: 15:50-17:20 | AY43: 5 | AZ43: Архитектура аппаратных средств | CL43: 57
AZ44: Тетенькин Д.А.
C45: 17:30-19:00 | E45: 6 | AW45: 17:30-19:00 | AY45: 6
C47: 19:10-20:40 | E47: 7 | AW47: 19:10-20:40 | AY47: 7
A49: =Даты!$B$5&" "&Даты!$C$5 -> Четверг 24.09 | C49: 8:30-10:00 | E49: 1 | F49: МДК 02.01 Технол разраб ПО | AR49: 16 | AU49: =Даты!$B$5&" "&Даты!$C$5 -> Четверг 24.09 | AW49: 8:30-10:00 | AY49: 1 | AZ49: Иностранный язык в ПД | CL49: 17
F50: Красноперов К.В. | AZ50: Кусакина О.В,
C51: 10:30-12:00 | E51: 2 | F51: МДК 02.01 Технол разраб ПО | AR51: 16 | AW51: 10:30-12:00 | AY51: 2 | AZ51: Иностранный язык в ПД | CL51: 17
F52: Красноперов К.В. | AZ52: Кусакина О.В,
C53: 12:10-13:40 | E53: 3 | AW53: 12:10-13:40 | AY53: 3
...

Sheet 3 курс
A1: Дни | C1: Часы | F1: ИСП 31-9 | AR1: Ауд. | AU1: Дни | AW1: Часы | AZ1: ИСП 32-9, ИСП 34-11 | CL1: Ауд.
A2: Недели | C2: Занятий | AU2: Недели | AW2: Занятий
A3: =Даты!$B$2&" "&Даты!$C$2 -> Понедельник 21.09 | C3: 8:30-9:30 | E3: 1 | AU3: =Даты!$B$2&" "&Даты!$C$2 -> Понедельник 21.09 | AW3: 8:30-9:30 | AY3: 1 | AZ3: Проект и раз веб-прил | CL3: 13
AZ4: Заляев Р.И.
C5: 10:00-11:00 | E5: 2 | AW5: 10:00-11:00 | AY5: 2 | AZ5: Проект и раз веб-прил | CL5: 13
AZ6: Заляев Р.И.
C7: 11:10-12:10 | E7: 3 | AW7: 11:10-12:10 | AY7: 3 | AZ7: Проект и раз веб-прил | CL7: 13
AZ8: Заляев Р.И.
C9: 12:10-12:55 | AW9: 12:10-12:55
C11: 12:55-13:40 | AW11: 12:55-13:40
C13: 13:40-14:40 | E13: 4 | AW13: 13:40-14:40 | AY13: 4
C15: 15:10-16:10 | E15: 5 | F15: МДК 03.01 Моделир и анализ ПО | AR15: 57 | AW15: 15:10-16:10 | AY15: 5
F16: Шадрина А.Ю.
C17: 16:20-17:20 | E17: 6 | F17: Проект и раз веб-прил | AR17: 13 | AW17: 16:20-17:20 | AY17: 6
F18: Заляев Р.И.
C19: 17:30-18:30 | E19: 7 | F19: Проект и раз веб-прил | AR19: 13 | AW19: 17:30-18:30 | AY19: 7
F20: Заляев Р.И.
A21: =Даты!$B$3&" "&Даты!$C$3 -> Вторник 22.09 | C21: 8:30-10:00 | E21: 1 | AU21: =Даты!$B$3&" "&Даты!$C$3 -> Вторник 22.09 | AW21: 8:30-10:00 | AY21: 1
C23: 10:30-12:00 | E23: 2 | AW23: 10:30-12:00 | AY23: 2 | AZ23: Иностранный язык в ПД | CL23: 8
AZ24: Филоксенова З.М.
C25: 12:10-13:40 | E25: 3 | AW25: 12:10-13:40 | AY25: 3 | AZ25: МДК 03.02 Управление проектами | CL25: 17
AZ26: Красноперов К.В.
C27: 13:50-15:20 | E27: 4 | F27: МДК 03.01 Моделир и анализ ПО | AR27: 57 | AW27: 13:50-15:20 | AY27: 4 | AZ27: МДК 03.02 Управление проектами | CL27: 17
F28: Шадрина А.Ю. | AZ28: Красноперов К.В.
C29: 15:50-17:20 | E29: 5 | F29: Физическая культура | AR29: Спорт зал | AW29: 15:50-17:20 | AY29: 5
F30: Чухланцева Г.Р.
C31: 17:30-19:00 | E31: 6 | F31: Иностранный язык в ПД | AR31: 83 | AW31: 17:30-19:00 | AY31: 6
F32: Филоксенова З.М.
C33: 19:10-20:40 | E33: 7 | AW33: 19:10-20:40 | AY33: 7
A35: =Даты!$B$4&" "&Даты!$C$4 -> Среда 23.09 | C35: 8:30-10:00 | E35: 1 | AU35: =Даты!$B$4&" "&Даты!$C$4 -> Среда 23.09 | AW35: 8:30-10:00 | AY35: 1
C37: 10:30-12:00 | E37: 2 | AW37: 10:30-12:00 | AY37: 2
C39: 12:10-13:40 | E39: 3 | AW39: 12:10-13:40 | AY39: 3 | AZ39: Компьютерные сети | CL39: 16
AZ40: Ваганов М.А.
C41: 13:50-15:20 | E41: 4 | F41: МДК 03.02 Управление проектами | AR41: 17 | AW41: 13:50-15:20 | AY41: 4 | AZ41: Д/З МДК 03.01 Моделир и анализ ПО | CL41: 13
F42: Красноперов К.В. | AZ42: Шадрина А.Ю.
C43: 15:50-17:20 | E43: 5 | F43: МДК 03.02 Управление проектами | AR43: 17 | AW43: 15:50-17:20 | AY43: 5 | AZ43: Физическая культура | CL43: Спорт зал
F44: Красноперов К.В. | AZ44: Демченков В.А.
C45: 17:30-19:00 | E45: 6 | F45: МДК 03.01 Моделир и анализ ПО | AR45: с/р | AW45: 17:30-19:00 | AY45: 6
F46: Шадрина А.Ю.
C47: 19:10-20:40 | E47: 7 | AW47: 19:10-20:40 | AY47: 7
...

Sheet 4 курс
A1: Дни | C1: Часы | F1: ИСП 41-9, ИСП 45-11 | AU1: Дни | AW1: Часы | AZ1: ИСП 43-9 | CL1: Ауд.
A2: Недели | C2: Занятий | AU2: Недели | AW2: Занятий
A3: =Даты!$B$2&" "&Даты!$C$2 -> Понедельник 21.09 | C3: 8:30-9:30 | E3: 1 | AU3: =Даты!$B$2&" "&Даты!$C$2 -> Понедельник 21.09 | AW3: 8:30-9:30 | AY3: 1
C5: 10:00-11:00 | E5: 2 | AW5: 10:00-11:00 | AY5: 2
C7: 11:10-12:10 | E7: 3 | AW7: 11:10-12:10 | AY7: 3
C9: 12:10-12:55 | AW9: 12:10-12:55
C11: 12:55-13:40 | AW11: 12:55-13:40
C13: 13:40-14:40 | E13: 4 | F13: МДК 06.04 Интел системы и техн | AR13: 16 | AW13: 13:40-14:40 | AY13: 4 | AZ13: Проект и раз веб-прил | CL13: 17
F14: Тетенькин Д.А. | AZ14: Шадрина А.Ю.
C15: 15:10-16:10 | E15: 5 | F15: Осн работы в 1С | AR15: 45 | AW15: 15:10-16:10 | AY15: 5 | AZ15: МДК 06.04 Интел системы и техн | CL15: 16
F16: Лобанова Л.П. | AZ16: Тетенькин Д.А.
C17: 16:20-17:20 | E17: 6 | F17: Осн работы в 1С | AR17: 45 | AW17: 16:20-17:20 | AY17: 6 | AZ17: МДК 06.04 Интел системы и техн | CL17: 16
F18: Лобанова Л.П. | AZ18: Тетенькин Д.А.
C19: 17:30-18:30 | E19: 7 | AW19: 17:30-18:30 | AY19: 7
A21: =Даты!$B$3&" "&Даты!$C$3 -> Вторник 22.09 | C21: 8:30-10:00 | E21: 1 | AU21: =Даты!$B$3&" "&Даты!$C$3 -> Вторник 22.09 | AW21: 8:30-10:00 | AY21: 1
C23: 10:30-12:00 | E23: 2 | AW23: 10:30-12:00 | AY23: 2
C25: 12:10-13:40 | E25: 3 | F25: Проект и раз веб-прил | AR25: 16 | AW25: 12:10-13:40 | AY25: 3
F26: Шадрина А.Ю.
C27: 13:50-15:20 | E27: 4 | F27: МДК 06.04 Интел системы и техн | AR27: 16 | AW27: 13:50-15:20 | AY27: 4 | AZ27: Станд, сертиф и тех документ | CL27: 88
F28: Тетенькин Д.А. | AZ28: Федорова Т.В.
C29: 15:50-17:20 | E29: 5 | F29: МДК 06.04 Интел системы и техн | AR29: 16 | AW29: 15:50-17:20 | AY29: 5 | AZ29: Проект и раз веб-прил | CL29: 57
F30: Тетенькин Д.А. | AZ30: Шадрина А.Ю.
C31: 17:30-19:00 | E31: 6 | AW31: 17:30-19:00 | AY31: 6 | AZ31: Проект и раз веб-прил | CL31: 57
AZ32: Шадрина А.Ю.
C33: 19:10-20:40 | E33: 7 | AW33: 19:10-20:40 | AY33: 7
A35: =Даты!$B$4&" "&Даты!$C$4 -> Среда 23.09 | C35: 8:30-10:00 | E35: 1 | AU35: =Даты!$B$4&" "&Даты!$C$4 -> Среда 23.09 | AW35: 8:30-10:00 | AY35: 1 | AZ35: Осн работы в 1С | CL35: 45
AZ36: Лобанова Л.П.
C37: 10:30-12:00 | E37: 2 | AW37: 10:30-12:00 | AY37: 2 | AZ37: Физическая культура | CL37: Спорт зал
AZ38: Чухланцева Г.Р.
C39: 12:10-13:40 | E39: 3 | AW39: 12:10-13:40 | AY39: 3 | AZ39: Иностранный язык в ПД | CL39: 6
AZ40: Филоксенова З.М.
C41: 13:50-15:20 | E41: 4 | F41: Иностранный язык в ПД | AR41: 6 | AW41: 13:50-15:20 | AY41: 4
F42: Филоксенова З.М.
C43: 15:50-17:20 | E43: 5 | F43: Проект и раз веб-прил | AR43: 13 | AW43: 15:50-17:20 | AY43: 5
F44: Шадрина А.Ю.
C45: 17:30-19:00 | E45: 6 | F45: Проект и раз веб-прил | AR45: 13 | AW45: 17:30-19:00 | AY45: 6
F46: Шадрина А.Ю.
C47: 19:10-20:40 | E47: 7 | AW47: 19:10-20:40 | AY47: 7
A49: =Даты!$B$5&" "&Даты!$C$5 -> Четверг 24.09 | C49: 8:30-10:00 | E49: 1 | AU49: =Даты!$B$5&" "&Даты!$C$5 -> Четверг 24.09 | AW49: 8:30-10:00 | AY49: 1 | AZ49: МДК 06.04 Интел системы и техн | CL49: 57
AZ50: Тетенькин Д.А.
...

Sheet Даты
B1: День | C1: Число
B2: Понедельник | C2: 21.09
B3: Вторник | C3: 22.09
B4: Среда | C4: 23.09
B5: Четверг | C5: 24.09
B6: Пятница | C6: 25.09
B7: Суббота | C7: 26.09
